Workbook

Sheet Sources
A1: Source Register
A2: Every hard input in this workbook points at one of these IDs. Links go to the exact document supporting the exact figure. The Basis column on each sheet states what to search for inside the document.
A4: ID | B4: Publisher | C4: Document and the exact figure it supports | D4: As of | E4: Link
A5: S01 | B5: SIFMA | C5: Research Quarterly: Equity & Related, 2Q26 - "Market cap of all US listed companies totaled $76.9T in 2Q26 (+16.5% Q/Q, +22.4% Y/Y) and the number of listed companies stood at 5,532 (+0.7% Q/Q, +2.1% Y/Y)." | D5: 30-Jun-2026 | E5: https://www.sifma.org/wp-content/uploads/2026/04/SIFMA-Research-Quarterly-Equity-and-Related-2Q26.pdf
A6: S02 | B6: SIFMA | C6: Research Quarterly: Equity & Related - landing page, all quarters | D6: 2026 | E6: https://www.sifma.org/research/statistics/research-quarterly-equity-and-related
A7: S03 | B7: Cboe Global Markets | C7: 2025 US Equities Year in Review - "average daily notional value (ADNV) increasing 43.3% year-over-year to $1.1 trillion"; ADV 17.6bn shares | D7: FY2025 | E7: https://www.cboe.com/insights/posts/2025-u-s-equities-year-in-review/
A8: S04 | B8: LSEG / FTSE Russell | C8: Russell Reconstitution June 2026 - "the total market capitalization of the Russell 3000 Index increased 29% from $58.4 trillion at the 2025 reconstitution to $75.6 trillion on this year's rank day (April 30, 2026)"; Russell 2000 "$3.5 trillion in 2026"; breakpoint "$5.7 billion in 2026" | D8: 30-Apr-2026 | E8: https://www.lseg.com/en/insights/ftse-russell/russell-reconstitution-june-2026-larger-leaders-stronger-small-caps
A9: S05 | B9: DTCC | C9: "Paving the Way to Tokenized DTC-Custodied Assets" - SEC no-action letter 11-Dec-2025; scope Russell 1000, major index ETFs, US Treasuries; three-year authorisation; rollout 2H26 | D9: 11-Dec-2025 | E9: https://www.dtcc.com/news/2025/december/11/paving-the-way-to-tokenized-dtc-custodied-assets
A10: S06 | B10: DTCC | C10: "DTCC Turns Tokenization into Reality" - live production trades processed 15-Jul-2026 with over 30 firms; Industry Working Group "has grown in recent months to more than 100 members and partners"; "sets the stage for the DTCC Tokenization Service to launch in October 2026" | D10: 15-Jul-2026 | E10: https://www.dtcc.com/press-releases/2026/dtcc-turns-tokenization-into-reality
A11: S07 | B11: DTCC | C11: "DTCC Advances Development of New Tokenization Service, Convenes 50+ Firms" - working group composition and named members | D11: 04-May-2026 | E11: https://www.dtcc.com/news/2026/may/04/dtcc-advances-development-of-new-tokenization-service
A12: S08 | B12: SEC (Federal Register) | C12: SR-NSCC-2025-017 - "decrease its 'value into the net' fee from $0.46 to $0.44 per million of processed value"; "implemented on January 1, 2026" | D12: 17-Dec-2025 | E12: https://www.federalregister.gov/documents/2025/12/17/2025-23068/self-regulatory-organizations-national-securities-clearing-corporation-notice-of-filing-and
A13: S09 | B13: DTCC | C13: Guide to the NSCC Fee Schedule - Clearance Activity, Value Into Net, Fee ID 2482. NOTE: the copy retrieved 10-Sep-2026 still displays 0.46; S08 is the authority for the 0.44 rate effective 01-Jan-2026 | D13: 2026 | E13: https://www.dtcc.com/-/media/Files/Downloads/legal/fee-guides/nsccfeeguide.pdf
A14: S10 | B14: S&P Global Market Intelligence (via Securities Finance Times) | C14: FY2025 securities lending - "a 27 per cent year-on-year (YoY) increase to US$14.9 billion"; "equities, which contributed US$11.5 billion"; "lendable assets increased 16 per cent to US$46.7 trillion"; "Average balances rose 20 per cent YoY to US$3.25 trillion" | D14: FY2025 | E14: https://www.securitiesfinancetimes.com/securitieslendingnews/industryarticle.php?article_id=228388
A15: S11 | B15: ICI | C15: Exchange-Traded Fund Data, July 2026 - "The combined assets of the nation's exchange-traded funds (ETFs) were $15.67 trillion in July"; Total Domestic Equity $10,090.4bn; 5,182 ETFs | D15: 31-Jul-2026 | E15: https://www.ici.org/research/stats/etf/etfs_04_26
... A22: S18 | B22: Congress.gov | C22: H.R.3633 Digital Asset Market Clarity Act, 119th Congress - bill text and status | D22: 2026 | E22: https://www.congress.gov/bill/119th-congress/house-bill/3633
A23: SX | B23: Bernstein | C23: Internal estimate or judgement. No public document supports the figure | D23: -

Sheet Assumptions
A1: US Tokenized Equity Market: TAM Sizing Model
A2: Assumptions & Market Segmentation
A4: US Equity Market Overview | F4: Source | G4: Link | H4: Status | I4: Src ID | J4: Basis / what to search in the source
A5: Total US listed companies (major exchanges) | B5: 5532 | F5: SIFMA Research Quarterly: Equity & Related, 2Q26 | G5: https://www.sifma.org/wp-content/uploads/2026/04/SIFMA-Research-Quarterly-Equity-and-Related-2Q26.pdf | H5: VERIFIED | I5: S01 | J5: Search the 2Q26 PDF, Executive Summary p1, for 'number of listed companies stood at 5,532'
A6: Total US equity market cap ($Bn) | B6: 76900 | F6: SIFMA Research Quarterly: Equity & Related, 2Q26 | G6: https://www.sifma.org/wp-content/uploads/2026/04/SIFMA-Research-Quarterly-Equity-and-Related-2Q26.pdf | H6: VERIFIED | I6: S01 | J6: Search the 2Q26 PDF, Executive Summary p1, for 'Market cap of all US listed companies totaled $76.9T'
A7: Total US equity ADV ($Bn) | B7: 1100 | F7: Cboe 2025 US Equities Year in Review | G7: https://www.cboe.com/insights/posts/2025-u-s-equities-year-in-review/ | H7: VERIFIED | I7: S03 | J7: Search the Cboe post for 'average daily notional value (ADNV) increasing 43.3% year-over-year to $1.1 trillion'
A9: ADV-Based Segmentation | F9: Source | G9: Link | H9: Status | I9: Src ID | J9: Basis / what to search in the source
B10: Low ADV | C10: Mid ADV | D10: High ADV | E10: Total / Check
A11: ADV threshold | B11: <$5M / day | C11: $5M - $50M / day | D11: >$50M / day
A12: Number of companies | B12: 3140 | C12: 1800 | D12: 592 | E12: =SUM(B12:D12) | F12: Bernstein estimate - ADV bucket split. Company counts rebased to the SIFMA 2Q26 total of 5,532 | G12: https://www.sifma.org/wp-content/uploads/2026/04/SIFMA-Research-Quarterly-Equity-and-Related-2Q26.pdf | H12: DERIVED | I12: S01 / SX | J12: Bucket split is a Bernstein estimate and is NOT in any public document. Only the 5,532 control total is verified - search S01 for it
A13: Aggregate market cap ($Bn) | B13: 3845 | C13: 13398 | D13: 59657 | E13: =SUM(B13:D13) | F13: Bernstein estimate - segment shares of 5.00% / 17.42% / 77.58% held constant, applied to the SIFMA 2Q26 total of $76.9T | G13: https://www.sifma.org/wp-content/uploads/2026/04/SIFMA-Research-Quarterly-Equity-and-Related-2Q26.pdf | H13: DERIVED | I13: S01 / SX | J13: Bucket split is a Bernstein estimate. Only the $76.9T control total is verified - search S01 for it
A14: % of total market cap | B14: =B13/$E13 | C14: =C13/$E13 | D14: =D13/$E13 | E14: =SUM(B14:D14) | H14: CALC | J14: Formula on this sheet
A15: Avg market cap per company ($Bn) | B15: =B13/B12 | C15: =C13/C12 | D15: =D13/D12 | H15: CALC | J15: Formula on this sheet
A17: Tokenization Penetration Assumptions (% of segment mkt cap)
A18: Rationale | B18: Early adopters: illiquid names benefit most from 24/7 trading, fractional access
A20: Year | B20: Low ADV Penetration | C20: Mid ADV Penetration | D20: High ADV Penetration | F20: Source / Rationale | G20: Link / Reference | H20: Status | I20: Src ID | J20: Basis / what to search in the source
A21: 2026 | B21: 0.001 | C21: 0 | D21: 0 | F21: Bernstein forecast - see Basis column | G21: https://www.dtcc.com/news/2025/december/11/paving-the-way-to-tokenized-dtc-custodied-assets | H21: FORECAST | I21: S05 | J21: 2026 anchor. DTC no-action letter dated 11-Dec-2025 permits tokenization only of Russell 1000 equities, major index ETFs and Treasuries, so onshore penetration starts near zero. Search S05 for 'Russell 1000'
A22: 2027 | B22: 0.005 | C22: 0.002 | D22: 0 | F22: Bernstein forecast - see Basis column | H22: FORECAST | I22: SX | J22: Assumes CLARITY Act does not complete in 2027. Search S18 for the bill's status history
A23: 2028 | B23: 0.015 | C23: 0.005 | D23: 0.001 | F23: Bernstein forecast - see Basis column | G23: https://www.dtcc.com/press-releases/2026/dtcc-turns-tokenization-into-reality | H23: FORECAST | I23: S06 | J23: First full year of the DTCC Tokenization Service. Search S06 for 'launch in October 2026'
A24: 2029 | B24: 0.035 | C24: 0.012 | D24: 0.003 | F24: Bernstein forecast - see Basis column | H24: FORECAST | I24: SX | J24: Assumes relief widens beyond the Russell 1000. The current letter runs three years from 11-Dec-2025; search S05 for the authorisation term
A25: 2030 | B25: 0.06 | C25: 0.025 | D25: 0.006 | F25: Bernstein forecast - see Basis column | G25: https://www.ici.org/research/stats/etf/etfs_04_26 | H25: FORECAST | I25: S11 | J25: ETF wrapper analogue at year 10 of adoption. Search S11 for domestic equity ETF net assets
A26: 2031 | B26: 0.09 | C26: 0.04 | D26: 0.01 | F26: Bernstein forecast - see Basis column | H26: FORECAST | I26: SX | J26: Judgement. No document supports a 2031 penetration rate
A27: 2032 | B27: 0.12 | C27: 0.06 | D27: 0.02 | F27: Bernstein forecast - see Basis column | H27: FORECAST | I27: SX | J27: Judgement. No document supports a 2032 penetration rate
A28: 2033 | B28: 0.15 | C28: 0.08 | D28: 0.03 | F28: Bernstein forecast - see Basis column | H28: FORECAST | I28: SX | J28: Judgement. No document supports a 2033 penetration rate
A29: 2034 | B29: 0.18 | C29: 0.1 | D29: 0.04 | F29: Bernstein forecast - see Basis column | H29: FORECAST | I29: SX | J29: Judgement. No document supports a 2034 penetration rate
A30: 2035 | B30: 0.2 | C30: 0.12 | D30: 0.05 | F30: Bernstein forecast - see Basis column | H30: FORECAST | I30: SX | J30: Terminal year. Bracketed by the ETF wrapper as the high case and the ADR wrapper as the low case
A32: Market Cap Growth Assumptions
A33: Annual equity market cap growth rate | B33: 0.05 | C33: Applied uniformly across segments | F33: Bernstein LT nominal equity return assumption (~5% = ~2% real + ~3% inflation) | G33: Bernstein internal — no public link | H33: FORECAST | I33: SX | J33: Long-run nominal equity market growth. Bernstein internal assumption, no public document

Sheet Projection
A1: US Tokenized Equity Market Cap Projection ($Bn)
B3: 2026 | C3: 2027 | D3: 2028 | E3: 2029 | F3: 2030 | G3: 2031 | H3: 2032 | I3: 2033 | J3: 2034 | K3: 2035
A4: SEGMENT MARKET CAP (GROWING AT EQUITY MKT GROWTH RATE)
A5: Low ADV segment market cap ($Bn) | B5: =Assumptions!B13 | C5: =B5*(1+Assumptions!B33) | D5: =C5*(1+Assumptions!B33) | E5: =D5*(1+Assumptions!B33) | F5: =E5*(1+Assumptions!B33) | G5: =F5*(1+Assumptions!B33) | H5: =G5*(1+Assumptions!B33) | I5: =H5*(1+Assumptions!B33) | J5: =I5*(1+Assumptions!B33) | K5: =J5*(1+Assumptions!B33)
A6: Mid ADV segment market cap ($Bn) | B6: =Assumptions!C13 | C6: =B6*(1+Assumptions!B33) | D6: =C6*(1+Assumptions!B33) | E6: =D6*(1+Assumptions!B33) | F6: =E6*(1+Assumptions!B33) | G6: =F6*(1+Assumptions!B33) | H6: =G6*(1+Assumptions!B33) | I6: =H6*(1+Assumptions!B33) | J6: =I6*(1+Assumptions!B33) | K6: =J6*(1+Assumptions!B33)
A7: High ADV segment market cap ($Bn) | B7: =Assumptions!D13 | C7: =B7*(1+Assumptions!B33) | D7: =C7*(1+Assumptions!B33) | E7: =D7*(1+Assumptions!B33) | F7: =E7*(1+Assumptions!B33) | G7: =F7*(1+Assumptions!B33) | H7: =G7*(1+Assumptions!B33) | I7: =H7*(1+Assumptions!B33) | J7: =I7*(1+Assumptions!B33) | K7: =J7*(1+Assumptions!B33)
A8: Total US equity market cap ($Bn) | B8: =SUM(B5:B7) | C8: =SUM(C5:C7) | D8: =SUM(D5:D7) | E8: =SUM(E5:E7) | F8: =SUM(F5:F7) | G8: =SUM(G5:G7) | H8: =SUM(H5:H7) | I8: =SUM(I5:I7) | ... K8: =SUM(K5:K7)
A10: TOKENIZATION PENETRATION RATES
A11: Low ADV penetration | B11: =Assumptions!B21 | C11: =Assumptions!B22 | D11: =Assumptions!B23 | E11: =Assumptions!B24 | F11: =Assumptions!B25 | G11: =Assumptions!B26 | H11: =Assumptions!B27 | I11: =Assumptions!B28 | J11: =Assumptions!B29 | K11: =Assumptions!B30
A12: Mid ADV penetration | B12: =Assumptions!C21 | C12: =Assumptions!C22 | D12: =Assumptions!C23 | E12: =Assumptions!C24 | F12: =Assumptions!C25 | G12: =Assumptions!C26 | H12: =Assumptions!C27 | I12: =Assumptions!C28 | J12: =Assumptions!C29 | K12: =Assumptions!C30
A13: High ADV penetration | B13: =Assumptions!D21 | C13: =Assumptions!D22 | D13: =Assumptions!D23 | E13: =Assumptions!D24 | F13: =Assumptions!D25 | G13: =Assumptions!D26 | H13: =Assumptions!D27 | I13: =Assumptions!D28 | J13: =Assumptions!D29 | K13: =Assumptions!D30
A15: TOKENIZED MARKET CAP BY SEGMENT ($Bn)
A16: Low ADV tokenized mkt cap ($Bn) | B16: =B5*B11 | C16: =C5*C11 | D16: =D5*D11 | E16: =E5*E11 | F16: =F5*F11 | G16: =G5*G11 | H16: =H5*H11 | I16: =I5*I11 | ... K16: =K5*K11
A17: Mid ADV tokenized mkt cap ($Bn) | B17: =B6*B12 | C17: =C6*C12 | D17: =D6*D12 | E17: =E6*E12 | F17: =F6*F12 | G17: =G6*G12 | H17: =H6*H12 | I17: =I6*I12 | ... K17: =K6*K12
A18: High ADV tokenized mkt cap ($Bn) | B18: =B7*B13 | C18: =C7*C13 | D18: =D7*D13 | E18: =E7*E13 | F18: =F7*F13 | G18: =G7*G13 | H18: =H7*H13 | I18: =I7*I13 | ... K18: =K7*K13
A20: Total tokenized equity market cap ($Bn) | B20: =SUM(B16:B18) | C20: =SUM(C16:C18) | D20: =SUM(D16:D18) | E20: =SUM(E16:E18) | F20: =SUM(F16:F18) | G20: =SUM(G16:G18) | H20: =SUM(H16:H18) | I20: =SUM(I16:I18) | ... K20: =SUM(K16:K18)
A21: Blended penetration (% of total mkt cap) | B21: =B20/B8 | C21: =C20/C8 | D21: =D20/D8 | E21: =E20/E8 | F21: =F20/F8 | G21: =G20/G8 | H21: =H20/H8 | I21: =I20/I8 | ... K21: =K20/K8
A23: CONTRIBUTION BREAKDOWN
A24: Low ADV % of tokenized total | B24: =IF(B20=0,0,B16/B20) | C24: =IF(C20=0,0,C16/C20) | D24: =IF(D20=0,0,D16/D20) | E24: =IF(E20=0,0,E16/E20) | F24: =IF(F20=0,0,F16/F20) | G24: =IF(G20=0,0,G16/G20) | H24: =IF(H20=0,0,H16/H20) | I24: =IF(I20=0,0,I16/I20) | ... K24: =IF(K20=0,0,K16/K20)
A25: Mid ADV % of tokenized total | B25: =IF(B20=0,0,B17/B20) | C25: =IF(C20=0,0,C17/C20) | D25: =IF(D20=0,0,D17/D20) | E25: =IF(E20=0,0,E17/E20) | F25: =IF(F20=0,0,F17/F20) | G25: =IF(G20=0,0,G17/G20) | H25: =IF(H20=0,0,H17/H20) | I25: =IF(I20=0,0,I17/I20) | ... K25: =IF(K20=0,0,K17/K20)
A26: High ADV % of tokenized total | B26: =IF(B20=0,0,B18/B20) | C26: =IF(C20=0,0,C18/C20) | D26: =IF(D20=0,0,D18/D20) | E26: =IF(E20=0,0,E18/E20) | F26: =IF(F20=0,0,F18/F20) | G26: =IF(G20=0,0,G18/G20) | H26: =IF(H20=0,0,H18/H20) | I26: =IF(I20=0,0,I18/I20) | ... K26: =IF(K20=0,0,K18/K20)
A28: IMPLIED TOKENIZED ISSUERS (APPROX)
A29: Low ADV issuers tokenized | B29: =Assumptions!B12*Assumptions!B21 | C29: =Assumptions!B12*Assumptions!B22 | D29: =Assumptions!B12*Assumptions!B23 | E29: =Assumptions!B12*Assumptions!B24 | F29: =Assumptions!B12*Assumptions!B25 | G29: =Assumptions!B12*Assumptions!B26 | H29: =Assumptions!B12*Assumptions!B27 | I29: =Assumptions!B12*Assumptions!B28 | J29: =Assumptions!B12*Assumptions!B29 | K29: =Assumptions!B12*Assumptions!B30
A30: Mid ADV issuers tokenized | B30: =Assumptions!C12*Assumptions!C21 | C30: =Assumptions!C12*Assumptions!C22 | D30: =Assumptions!C12*Assumptions!C23 | E30: =Assumptions!C12*Assumptions!C24 | F30: =Assumptions!C12*Assumptions!C25 | G30: =Assumptions!C12*Assumptions!C26 | H30: =Assumptions!C12*Assumptions!C27 | I30: =Assumptions!C12*Assumptions!C28 | J30: =Assumptions!C12*Assumptions!C29 | K30: =Assumptions!C12*Assumptions!C30
A31: High ADV issuers tokenized | B31: =Assumptions!D12*Assumptions!D21 | C31: =Assumptions!D12*Assumptions!D22 | D31: =Assumptions!D12*Assumptions!D23 | E31: =Assumptions!D12*Assumptions!D24 | F31: =Assumptions!D12*Assumptions!D25 | G31: =Assumptions!D12*Assumptions!D26 | H31: =Assumptions!D12*Assumptions!D27 | I31: =Assumptions!D12*Assumptions!D28 | J31: =Assumptions!D12*Assumptions!D29 | K31: =Assumptions!D12*Assumptions!D30
A32: Total tokenized issuers | B32: =SUM(B29:B31) | C32: =SUM(C29:C31) | D32: =SUM(D29:D31) | E32: =SUM(E29:E31) | F32: =SUM(F29:F31) | G32: =SUM(G29:G31) | H32: =SUM(H29:H31) | I32: =SUM(I29:I31) | ... K32: =SUM(K29:K31)

Sheet Revenue Pools
A1: Tokenized US Equity Revenue Pool Analysis ($M)
A2: Annual revenue by segment, linked to base case tokenized market cap projection
B4: Assumption | C4: 2026 | D4: 2027 | E4: 2028 | F4: 2029 | G4: 2030 | H4: 2031 | I4: 2032 | J4: 2033 | K4: 2034 | L4: 2035 | M4: Source / Rationale | N4: Source Link | O4: Status | P4: Src ID | Q4: Basis / what to search in the source
A5: INPUTS (FROM PROJECTION SHEET)
A6: Total tokenized equity mkt cap ($Bn) | C6: =Projection!B20 | D6: =Projection!C20 | E6: =Projection!D20 | F6: =Projection!E20 | G6: =Projection!F20 | H6: =Projection!G20 | I6: =Projection!H20 | J6: =Projection!I20 | ... L6: =Projection!K20
A7: Total tokenized equity mkt cap ($M) | C7: =C6*1000 | D7: =D6*1000 | E7: =E6*1000 | F7: =F6*1000 | G7: =G6*1000 | H7: =H6*1000 | I7: =I6*1000 | J7: =J6*1000 | ... L7: =L6*1000 | M7: Conversion for revenue calc
A9: 1. TRADING REVENUE
A10: Annual turnover velocity (x mkt cap) | C10: 0.8 | D10: 1 | E10: 1.2 | F10: 1.4 | G10: 1.6 | H10: 1.8 | I10: 2 | J10: 2.2 | K10: 2.4 | L10: 2.5 | M10: Turnover implied by Cboe FY25 ADV of $1.1T x 251 trading days over US market cap. The 2.5x terminal assumption is NOT consistent with that arithmetic - see Audit | N10: https://www.cboe.com/insights/posts/2025-u-s-equities-year-in-review/ | O10: FORECAST | P10: S03 | Q10: Ramp is judgement. Search S03 for the $1.1T ADNV figure that should anchor the terminal value
A11: Implied annual trading volume ($M) | C11: =C7*C10 | D11: =D7*D10 | E11: =E7*E10 | F11: =F7*F10 | G11: =G7*G10 | H11: =H7*H10 | I11: =I7*I10 | J11: =J7*J10 | ... L11: =L7*L10
A12: Blended take rate (bps on volume) | C12: 8 | D12: 7 | E12: 6 | F12: 5.5 | G12: 5 | H12: 4.5 | I12: 4 | J12: 3.5 | K12: 3 | L12: 2.5 | M12: Exchange fees: Cboe 2025 net capture ~$0.002/100 shares; spread: SIFMA Compendium 2025 equity market structure | N12: https://www.cboe.com/insights/posts/2025-u-s-equities-year-in-review/ | O12: FORECAST | P12: S03 | Q12: Search S03 for net capture. Take rate ramp itself is judgement
A13: Trading revenue ($M) | C13: =C11*C12/10000 | D13: =D11*D12/10000 | E13: =E11*E12/10000 | F13: =F11*F12/10000 | G13: =G11*G12/10000 | H13: =H11*H12/10000 | I13: =I11*I12/10000 | J13: =J11*J12/10000 | ... L13: =L11*L12/10000
A15: 2. MARGIN & SECURITIES LENDING REVENUE
A16: % of tokenized mkt cap available for lending | C16: 0.05 | D16: 0.08 | E16: 0.1 | F16: 0.12 | G16: 0.14 | H16: 0.15 | I16: 0.16 | J16: 0.17 | K16: 0.18 | L16: 0.2 | M16: Sec lending market: S&P Global Market Intelligence Securities Finance data (15-20% of float lent) | N16: https://www.spglobal.com/marketintelligence/en/campaigns/securities-finance | O16: FORECAST | P16: S10 | Q16: Search S10 for 'lendable assets increased 16 per cent to US$46.7 trillion'
A17: Lendable pool ($M) | C17: =C7*C16 | D17: =D7*D16 | E17: =E7*E16 | F17: =F7*F16 | G17: =G7*G16 | H17: =H7*H16 | I17: =I7*I16 | J17: =J7*J16 | ... L17: =L7*L16
A18: Utilization rate | C18: 0.15 | D18: 0.18 | E18: 0.22 | F18: 0.25 | G18: 0.28 | H18: 0.3 | I18: 0.32 | J18: 0.33 | K18: 0.34 | L18: 0.35 | M18: Utilization 25-35%: S&P Global Sec Finance quarterly dashboard (US equity avg) | N18: https://www.spglobal.com/marketintelligence/en/campaigns/securities-finance | O18: FORECAST | P18: S10 | Q18: Search S10 for 'Average balances rose 20 per cent YoY to US$3.25 trillion'. Implied utilisation 3.25/46.7 = 6.96%, well below the 15-35% modelled here
A19: On-loan balance ($M) | C19: =C17*C18 | D19: =D17*D18 | E19: =E17*E18 | F19: =F17*F18 | G19: =G17*G18 | H19: =H17*H18 | I19: =I17*I18 | J19: =J17*J18 | ... L19: =L17*L18
A20: Avg lending fee (bps, annualized) | C20: 50 | D20: 45 | E20: 40 | F20: 38 | G20: 35 | H20: 32 | I20: 30 | J20: 28 | K20: 26 | L20: 25 | M20: GC rate 25-40bps, specials higher: S&P Global Sec Finance; also DataLend data | N20: https://www.spglobal.com/marketintelligence/en/campaigns/securities-finance | O20: FORECAST | P20: S10 | Q20: Implied average fee = $14.9bn revenue over $3.25T on-loan = 45.8bps. Search S10 for both figures
A21: Gross lending revenue ($M) | C21: =C19*C20/10000 | D21: =D19*D20/10000 | E21: =E19*E20/10000 | F21: =F19*F20/10000 | G21: =G19*G20/10000 | H21: =H19*H20/10000 | I21: =I19*I20/10000 | J21: =J19*J20/10000 | ... L21: =L19*L20/10000
A22: Platform share of lending revenue (%) | C22: 0.35 | D22: 0.33 | E22: 0.3 | F22: 0.28 | G22: 0.27 | H22: 0.25 | I22: 0.24 | J22: 0.23 | K22: 0.22 | L22: 0.2 | M22: Agent lender split ~20-35%: industry standard per State Street, BNY, JPM sec lending disclosures | N22: Bernstein estimate — no single public link | O22: FORECAST | P22: SX | Q22: Agent lender split. No public document supports the percentage
A23: Margin & sec lending revenue ($M) | C23: =C21*C22 | D23: =D21*D22 | E23: =E21*E22 | F23: =F21*F22 | G23: =G21*G22 | H23: =H21*H22 | I23: =I21*I22 | J23: =J21*J22 | ... L23: =L21*L22
A25: 3. PRIME BROKERAGE & CUSTODY REVENUE
A26: % of tokenized mkt cap under prime/custody | C26: 0.3 | D26: 0.35 | E26: 0.4 | F26: 0.45 | G26: 0.5 | H26: 0.55 | I26: 0.58 | J26: 0.6 | K26: 0.62 | L26: 0.65 | M26: Institutional AUM under prime ~60-70%: estimated from COIN Institutional Q1 2026 10-Q, prime balances vs total platform | N26: https://www.sec.gov/cgi-bin/browse-edgar?action=getcompany&CIK=COIN&type=10-Q&dateb=&owner=include&count=10&search_text=&action=getcompany | O26: FORECAST | P26: SX | Q26: No public document supports the prime/custody share
A27: Assets under prime/custody ($M) | C27: =C7*C26 | D27: =D7*D26 | E27: =E7*E26 | F27: =F7*F26 | G27: =G7*G26 | H27: =H7*H26 | I27: =I7*I26 | J27: =J7*J26 | ... L27: =L7*L26
A28: Blended custody + prime fee (bps on AUC) | C28: 12 | D28: 11 | E28: 10 | F28: 9 | G28: 8 | H28: 7 | I28: 6.5 | J28: 6 | K28: 5.5 | L28: 5 | M28: Digital custody 10-50bps: COIN 2025 10-K (custody revenue / AUC); trad custody 1-5bps: BNY 10-K | N28: https://www.sec.gov/cgi-bin/browse-edgar?action=getcompany&CIK=COIN&type=10-K&dateb=&owner=include&count=10&search_text=&action=getcompany | O28: FORECAST | P28: SX | Q28: No public document supports the blended custody fee ramp
A29: Prime brokerage & custody revenue ($M) | C29: =C27*C28/10000 | D29: =D27*D28/10000 | E29: =E27*E28/10000 | F29: =F27*F28/10000 | G29: =G27*G28/10000 | H29: =H27*H28/10000 | I29: =I27*I28/10000 | J29: =J27*J28/10000 | ... L29: =L27*L28/10000
A31: 4. NEW ISSUANCE & TOKENIZATION FEES
A32: New issuers tokenizing per year | C32: =Projection!B32 | D32: =Projection!C32-Projection!B32 | E32: =Projection!D32-Projection!C32 | F32: =Projection!E32-Projection!D32 | G32: =Projection!F32-Projection!E32 | H32: =Projection!G32-Projection!F32 | I32: =Projection!H32-Projection!G32 | J32: =Projection!I32-Projection!H32 | K32: =Projection!J32-Projection!I32 | L32: =Projection!K32-Projection!J32 | M32: Incremental new tokenized issuers per year, from Projection sheet
A33: Avg issuance / tokenization fee per issuer ($K) | C33: 500 | D33: 450 | E33: 400 | F33: 375 | G33: 350 | H33: 325 | I33: 300 | J33: 275 | K33: 250 | L33: 225 | M33: IPO fees 3-7%: SIFMA Fact Book 2025 Table 6.5; tokenization simpler — Bernstein est $200-500K | N33: https://www.sifma.org/research/statistics/fact-book | O33: FORECAST | P33: SX | Q33: Tokenization fee per issuer. Bernstein estimate, no public pricing exists
A34: Issuance fee revenue ($M) | C34: =C32*C33/1000 | D34: =D32*D33/1000 | E34: =E32*E33/1000 | F34: =F32*F33/1000 | G34: =G32*G33/1000 | H34: =H32*H33/1000 | I34: =I32*I33/1000 | J34: =J32*J33/1000 | ... L34: =L32*L33/1000
A35: Annual TA / record-keeping fee per issuer ($K) | C35: 150 | D35: 145 | E35: 140 | F35: 135 | G35: 130 | H35: 125 | I35: 120 | J35: 115 | K35: 110 | L35: 100 | M35: TA fees ~$50-150K/yr: Computershare/AST pricing — estimated from Computershare FY25 annual report | N35: Verify on terminal — no direct public pricing page | O35: UNVERIFIED | P35: SX | Q35: Transfer agent pricing is not published by Computershare, Continental or Equiniti. Figure cannot be sourced
A36: Cumulative tokenized issuers | C36: =Projection!B32 | D36: =Projection!C32 | E36: =Projection!D32 | F36: =Projection!E32 | G36: =Projection!F32 | H36: =Projection!G32 | I36: =Projection!H32 | J36: =Projection!I32 | ... L36: =Projection!K32
A37: Annual TA / record-keeping revenue ($M) | C37: =C36*C35/1000 | D37: =D36*D35/1000 | E37: =E36*E35/1000 | F37: =F36*F35/1000 | G37: =G36*G35/1000 | H37: =H36*H35/1000 | I37: =I36*I35/1000 | J37: =J36*J35/1000 | ... L37: =L36*L35/1000
A38: Total issuance + TA revenue ($M) | C38: =C34+C37 | D38: =D34+D37 | E38: =E34+E37 | F38: =F34+F37 | G38: =G34+G37 | H38: =H34+H37 | I38: =I34+I37 | J38: =J34+J37 | ... L38: =L34+L37
A40: 5. MARKET DATA & INDEX LICENSING
A41: Market data rev as % of trading rev | C41: 0.1 | D41: 0.12 | E41: 0.14 | F41: 0.15 | G41: 0.16 | H41: 0.17 | I41: 0.18 | J41: 0.19 | K41: 0.2 | L41: 0.2 | M41: Market data = 15-25% of exchange rev: ICE 2025 10-K (Data Services segment), NDAQ 2025 10-K (Market Technology + Info Services) | N41: https://www.sec.gov/cgi-bin/browse-edgar?action=getcompany&company=intercontinental+exchange&CIK=&type=10-K&dateb=&owner=include&count=5&search_text=&action=getcompany
A42: Market data & index licensing revenue ($M) | C42: =C13*C41 | D42: =D13*D41 | E42: =E13*E41 | F42: =F13*F41 | G42: =G13*G41 | H42: =H13*H41 | I42: =I13*I41 | J42: =J13*J41 | ... L42: =L13*L41
A44: 6. SETTLEMENT & CLEARING FEES
A45: Number of trades (M, implied) | C45: =C11/C46 | D45: =D11/D46 | E45: =E11/E46 | F45: =F11/F46 | G45: =G11/G46 | H45: =H11/H46 | I45: =I11/I46 | J45: =J11/J46 | ... L45: =L11/L46
A46: Avg trade size ($) | C46: 5000 | D46: 8000 | E46: 10000 | F46: 12000 | G46: 15000 | H46: 18000 | I46: 22000 | J46: 28000 | K46: 35000 | L46: 42000 | M46: US equity avg trade size: Cboe market share page (notional / shares); retail skews smaller | N46: https://www.cboe.com/us/equities/market_share/ | O46: FORECAST | P46: SX | Q46: Average trade size. The Cboe market share page previously cited reports share by venue, not trade size, and does not support this row
A47: Settlement fee per trade ($) | C47: 0.1 | D47: 0.09 | E47: 0.08 | F47: 0.07 | G47: 0.06 | H47: 0.05 | I47: 0.05 | J47: 0.04 | K47: 0.04 | L47: 0.03 | M47: NSCC value-into-net fee is $0.44 per MILLION OF NOTIONAL, not per trade. The $/trade figures below are not supported by this source - see Audit | N47: https://www.federalregister.gov/documents/2025/12/17/2025-23068/self-regulatory-organizations-national-securities-clearing-corporation-notice-of-filing-and | O47: UNVERIFIED | P47: S08 | Q47: MISMATCH: the cited NSCC fee is $0.44 per million of notional. A per-trade fee of $0.03-0.10 is a different unit and is not supported. Search S08 for 'per million of processed value'
...

Sheet Scenarios
A1: Scenario Sensitivity: Terminal Year (2035) Tokenized Market Cap
A3: Terminal penetration rate assumptions
B4: Bear | C4: Base | D4: Bull | G4: Status | H4: Src ID | I4: Basis / what to search in the source
A5: Low ADV terminal penetration | B5: 0.08 | C5: 0.2 | D5: 0.35 | F5: Source: Bernstein scenario analysis | G5: FORECAST | H5: SX | I5: Terminal penetration, low ADV. Scenario judgement
A6: Mid ADV terminal penetration | B6: 0.04 | C6: 0.12 | D6: 0.25 | G6: FORECAST | H6: SX | I6: Terminal penetration, mid ADV. Scenario judgement
A7: High ADV terminal penetration | B7: 0.01 | C7: 0.05 | D7: 0.12 | G7: FORECAST | H7: SX | I7: Terminal penetration, high ADV. Scenario judgement
A9: Terminal year (2035) segment mkt cap ($Bn)
A10: Low ADV mkt cap ($Bn, 2035E) | B10: =Assumptions!B13*(1+Assumptions!B33)^9
A11: Mid ADV mkt cap ($Bn, 2035E) | B11: =Assumptions!C13*(1+Assumptions!B33)^9
A12: High ADV mkt cap ($Bn, 2035E) | B12: =Assumptions!D13*(1+Assumptions!B33)^9
A14: Tokenized market cap by scenario ($Bn)
B15: Bear | C15: Base | D15: Bull
A16: Low ADV tokenized ($Bn) | B16: =$B$10*B5 | C16: =$B$10*C5 | D16: =$B$10*D5
A17: Mid ADV tokenized ($Bn) | B17: =$B$11*B6 | C17: =$B$11*C6 | D17: =$B$11*D6
A18: High ADV tokenized ($Bn) | B18: =$B$12*B7 | C18: =$B$12*C7 | D18: =$B$12*D7
A20: Total tokenized equity mkt cap ($Bn) | B20: =SUM(B16:B18) | C20: =SUM(C16:C18) | D20: =SUM(D16:D18)
A21: Blended penetration | B21: =B20/($B$10+$B$11+$B$12) | C21: =C20/($B$10+$B$11+$B$12) | D21: =D20/($B$10+$B$11+$B$12)

Sheet Historical Analogues
A1: Historical Analogues: ETF & ADR Annual Growth Data
A2: Annual data series for benchmarking tokenized equity penetration assumptions
A4: US ETF MARKET — ANNUAL DATA (1993–2025) | G4: US ADR MARKET — ANNUAL DATA (1990–2025)
A5: Year | B5: ETF AUM ($Bn) | C5: US Eq Mkt Cap ($Bn) | D5: ETF Penetration (%) | E5: # of ETFs | G5: Year | H5: ADR Trading Val ($Bn/yr) | I5: US Eq Trading Val ($Bn/yr) | J5: ADR % of Trading | K5: ADR Mkt Cap ($Bn) | L5: US Eq Mkt Cap ($Bn) | M5: ADR % of Mkt Cap | N5: Status (ETF series) | O5: Src ID | P5: Basis / what to search in the source
A6: 1993 | B6: 0.5 | C6: 5137 | D6: =B6/C6 | E6: 1 | G6: 1990 | H6: 75 | I6: 1325 | J6: =H6/I6 | K6: 120 | L6: 3060 | M6: =K6/L6 | N6: UNVERIFIED | O6: SX | P6: ETF annual series. ICI publishes ETF net assets by year - search the ICI Fact Book chapter tables. Values in this sheet are not tied to a specific table and have not been checked line by line
A7: 1994 | B7: 0.4 | C7: 5068 | D7: =B7/C7 | E7: 1 | G7: 1991 | H7: 100 | I7: 1520 | J7: =H7/I7 | K7: 165 | L7: 4090 | M7: =K7/L7 | N7: UNVERIFIED | O7: SX | P7: ETF annual series. ICI publishes ETF net assets by year - search the ICI Fact Book chapter tables. Values in this sheet are not tied to a specific table and have not been checked line by line
A8: 1995 | B8: 1.1 | C8: 6858 | D8: =B8/C8 | E8: 2 | G8: 1992 | H8: 110 | I8: 1745 | J8: =H8/I8 | K8: 170 | L8: 4485 | M8: =K8/L8 | N8: UNVERIFIED | O8: SX | P8: ETF annual series. ICI publishes ETF net assets by year - search the ICI Fact Book chapter tables. Values in this sheet are not tied to a specific table and have not been checked line by line
A9: 1996 | B9: 2.4 | C9: 8484 | D9: =B9/C9 | E9: 19 | G9: 1993 | H9: 135 | I9: 2081 | J9: =H9/I9 | K9: 210 | L9: 5137 | M9: =K9/L9 | N9: UNVERIFIED | O9: SX | P9: ETF annual series. ICI publishes ETF net assets by year - search the ICI Fact Book chapter tables. Values in this sheet are not tied to a specific table and have not been checked line by line
A10: 1997 | B10: 6.7 | C10: 10880 | D10: =B10/C10 | E10: 19 | G10: 1994 | H10: 140 | I10: 2454 | J10: =H10/I10 | K10: 200 | L10: 5068 | M10: =K10/L10 | N10: UNVERIFIED | O10: SX | P10: ETF annual series. ICI publishes ETF net assets by year - search the ICI Fact Book chapter tables. Values in this sheet are not tied to a specific table and have not been checked line by line
A11: 1998 | B11: 16 | C11: 13451 | D11: =B11/C11 | E11: 29 | G11: 1995 | H11: 152 | I11: 3083 | J11: =H11/I11 | K11: 310 | L11: 6858 | M11: =K11/L11 | N11: UNVERIFIED | O11: SX | P11: ETF annual series. ICI publishes ETF net assets by year - search the ICI Fact Book chapter tables. Values in this sheet are not tied to a specific table and have not been checked line by line
A12: 1999 | B12: 34 | C12: 16635 | D12: =B12/C12 | E12: 30 | G12: 1996 | H12: 195 | I12: 4064 | J12: =H12/I12 | K12: 405 | L12: 8484 | M12: =K12/L12 | N12: UNVERIFIED | O12: SX | P12: ETF annual series. ICI publishes ETF net assets by year - search the ICI Fact Book chapter tables. Values in this sheet are not tied to a specific table and have not been checked line by line
A13: 2000 | B13: 66 | C13: 15104 | D13: =B13/C13 | E13: 80 | G13: 1997 | H13: 275 | I13: 5778 | J13: =H13/I13 | K13: 520 | L13: 10880 | M13: =K13/L13 | N13: UNVERIFIED | O13: SX | P13: ETF annual series. ICI publishes ETF net assets by year - search the ICI Fact Book chapter tables. Values in this sheet are not tied to a specific table and have not been checked line by line
A14: 2001 | B14: 84 | C14: 13855 | D14: =B14/C14 | E14: 102 | G14: 1998 | H14: 340 | I14: 7318 | J14: =H14/I14 | K14: 580 | L14: 13451 | M14: =K14/L14 | N14: UNVERIFIED | O14: SX | P14: ETF annual series. ICI publishes ETF net assets by year - search the ICI Fact Book chapter tables. Values in this sheet are not tied to a specific table and have not been checked line by line
A15: 2002 | B15: 102 | C15: 10049 | D15: =B15/C15 | E15: 113 | G15: 1999 | H15: 597 | I15: 14223 | J15: =H15/I15 | K15: 980 | L15: 16635 | M15: =K15/L15 | N15: UNVERIFIED | O15: SX | P15: ETF annual series. ICI publishes ETF net assets by year - search the ICI Fact Book chapter tables. Values in this sheet are not tied to a specific table and have not been checked line by line
A16: 2003 | B16: 151 | C16: 14266 | D16: =B16/C16 | E16: 119 | G16: 2000 | H16: 560 | I16: 14954 | J16: =H16/I16 | K16: 850 | L16: 15104 | M16: =K16/L16 | N16: UNVERIFIED | O16: SX | P16: ETF annual series. ICI publishes ETF net assets by year - search the ICI Fact Book chapter tables. Values in this sheet are not tied to a specific table and have not been checked line by line
A17: 2004 | B17: 228 | C17: 16324 | D17: =B17/C17 | E17: 152 | G17: 2001 | H17: 382 | I17: 10311 | J17: =H17/I17 | K17: 550 | L17: 13855 | M17: =K17/L17 | N17: UNVERIFIED | O17: SX | P17: ETF annual series. ICI publishes ETF net assets by year - search the ICI Fact Book chapter tables. Values in this sheet are not tied to a specific table and have not been checked line by line
... A38: 2025 | B38: 13460 | C38: 64500 | D38: =B38/C38 | E38: 4200 | G38: 2022 | H38: 1180 | I38: 53200 | J38: =H38/I38 | K38: 3500 | L38: 40360 | M38: =K38/L38 | N38: UNVERIFIED | O38: SX | P38: ETF annual series. ICI publishes ETF net assets by year - search the ICI Fact Book chapter tables. Values in this sheet are not tied to a specific table and have not been checked line by line
G39: 2023 | H39: 1250 | I39: 56500 | J39: =H39/I39 | K39: 3900 | L39: 50788 | M39: =K39/L39
A40: Summary | G40: 2024 | H40: 1350 | I40: 59400 | J40: =H40/I40 | K40: 3950 | L40: 55200 | M40: =K40/L40
A41: Yr 5 | B41: =B10 | D41: =D10 | G41: 2025 | H41: 1400 | I41: 62000 | J41: =H41/I41 | K41: 4000 | L41: 58000 | M41: =K41/L41
A42: Yr 10 | B42: =B15 | D42: =D15
A43: Yr 15 | B43: =B20 | D43: =D20 | G43: Summary
A44: Yr 20 | B44: =B25 | D44: =D25 | G44: Avg ADR % trading (all years) | J44: =AVERAGE(J6:J41)
A45: Yr 30 | B45: =B35 | D45: =D35 | G45: Avg ADR % mkt cap (all years) | M45: =AVERAGE(M6:M41)
A46: Yr 32 | B46: =B38 | D46: =D38 | G46: Peak ADR % trading | J46: =MAX(J6:J41)
G47: Peak ADR % mkt cap | M47: =MAX(M6:M41)
A48: Takeaway | B48: ETFs: <1% penetration through year 10; inflection around year 12-14 (~2-3%); crossed 5% at ~year 17; now ~18% at year 32. First decade = infrastructure + regulatory build; second decade = exponential adoption. | G48: Min ADR % trading | J48: =MIN(J6:J41)
G50: Takeaway | H50: ADRs: trading share ranged 2-6% over 35 years — remarkably stable niche, never achieved mass penetration. Mkt cap share higher at 4-11%, reflecting larger-cap bias in ADR listings. ADRs are a 'new wrapper for cross-border access' analogue — tokenization of US equities for global investors mirrors this pattern. But tokenization also offers settlement/collateral benefits that ADRs don't, suggesting higher terminal penetration.
A51: Sources | B51: ICI Fact Book
A52: ETF.com | B52: ETF.com
A53: NOTE: the ADR series (columns G-M) carries no source in the original workbook and has not been verified. BNY publishes DR market data - see Audit. | B53: SIFMA Capital Markets Fact Book | G53: Sources | H53: BNY Mellon DR Directory
A54: ETF AUM 1993-2023 | B54: ICI 2025 Fact Book Table 3.1 (ETF total net assets, annual) | D54: https://www.icifactbook.org/pdf/2025-factbook.pdf | G54: ADR trading value & programs | H54: BNY Mellon Depositary Receipts Annual Market Review (2024 edition) | J54: https://www.adrbnymellon.com/market-review
A55: ETF AUM 2024 | B55: ICI '5 Takeaways from 2025 Fact Book' — AUM crossed $10T | D55: https://www.ici.org/25-view-factbook-takeaways | G55: ADR mkt cap (outstanding) | H55: BNY Mellon DR Directory — current ADR outstanding | J55: https://www.adrbnymellon.com/directory/dr-directory
A56: ETF AUM 2025 | B56: American Century: US ETF AUM $13.46T at YE2025 | D56: https://www.americancentury.com/insights/etfs-defying-gravity/ | G56: US equity trading volume | H56: SIFMA 2025 Fact Book, Table 7.3 (equity trading volumes) | J56: https://www.sifma.org/research/statistics/fact-book
A57: US equity mkt cap | B57: SIFMA 2025 Capital Markets Fact Book, Table 6.1 | D57: https://www.sifma.org/research/statistics/fact-book | G57: US equity mkt cap (ref) | H57: World Federation of Exchanges — annual statistics | J57: https://www.world-exchanges.org/our-work/statistics
A58: # of ETFs | B58: ICI monthly ETF statistical releases | D58: https://www.ici.org/research/stats/etf_flows | G58: Pre-2000 ADR values | H58: Bernstein estimates from WFE aggregates — verify against BNY archive | J58: Verify on terminal
A59: 2024-2025E figures | B59: Bernstein estimates where ICI/SIFMA actuals not yet published
B60: Launch | C60: Yr 5 Pen. | D60: Yr 10 Pen. | E60: Yr 15 Pen. | F60: Yr 20 Pen. | G60: Current Pen. | H60: Terminal View | I60: Primary Driver
A61: US ETFs | B61: 1993 | C61: =D10 | D61: =D15 | E61: =D20 | F61: =D25 | G61: =D38 | H61: 20-25% | I61: New product wrapper; tax efficiency
A62: US ADRs | B62: 1990 | C62: =J10 | D62: =J15 | E62: =J20 | F62: =J25 | G62: =J41 | H62: 2-5% | I62: Cross-border access wrapper; stable niche
...

Sheet Audit
A1: Audit: what changed, what is verified, what is not
A2: Prepared 10-Sep-2026. Every source below was opened and read in full; figures are quoted verbatim in the Sources tab.
A4: # | B4: Sheet / cell | C4: Issue found | D4: Action taken
A5: 1 | B5: Assumptions B5, B6 | C5: Market cap $66.0T and 5,492 listed companies were SIFMA 1Q26 figures. | D5: Updated to SIFMA 2Q26: $76.9T and 5,532 companies. Verified verbatim - see S01.
A6: 2 | B6: Assumptions B12:D13 | C6: Segment splits summed to the stale 1Q26 totals. | D6: Rebased to the 2Q26 totals holding the segment shares constant. The bucket split itself remains an unsourced Bernstein estimate and is marked DERIVED.
A7: 3 | B7: Assumptions G21 | C7: Cited a 'DTCC Dec 2025 SEC no-action letter' but linked to sec.gov/files/rules/sro/nscc/2025/34-104376.pdf, which is the NSCC Rules document and does not contain a no-action letter. | D7: Replaced with the DTCC release of 11-Dec-2025 (S05).
A8: 4 | B8: Assumptions G22:G30 | C8: Penetration assumptions carried links to nyse.com, figure.com and newsroom.aboutrobinhood.com homepages, and a Congress.gov URL ending at 'house-bill/' with no bill number. None of these evidence a penetration rate. | D8: Links removed. Rows marked FORECAST with the reasoning stated in the Basis column. Where a document genuinely informs the year, it is cited (S05, S06, S11).
A9: 5 | B9: Assumptions G25 | C9: Stated 'ICI 2025 Fact Book: ETF AUM crossed $10T in 2024'. | D9: ICI July 2026 data now reads $15.67T total ETF assets and $10,090.4bn domestic equity. Cited as S11. Note total ETF assets include bond, commodity and international funds and are not a US equity penetration measure.
A10: 6 | B10: Revenue Pools N47, N89 | C10: NSCC $0.44 fee was sourced to sec.gov/files/rules/sro/nscc/2025/34-104376.pdf, which is the NSCC Rules document, not the fee filing. | D10: Repointed to SR-NSCC-2025-017 in the Federal Register (S08), which states verbatim: 'decrease its value into the net fee from $0.46 to $0.44 per million of processed value', implemented 01-Jan-2026.
A11: 7 | B11: Revenue Pools row 47 | C11: UNIT MISMATCH. The model applies a settlement fee of $0.10 to $0.03 PER TRADE while citing an NSCC fee that is charged PER MILLION OF NOTIONAL. The two are not the same quantity. | D11: Row left as built to avoid restructuring the model, but marked UNVERIFIED. At $0.44 per million, a $5,000 trade attracts $0.0022, roughly 45x below the $0.10 modelled for 2026. Settlement revenue is overstated on the current basis.
A12: 8 | B12: Revenue Pools row 96 | C12: 'DTCC tokenization authority' was sourced to Wikipedia. | D12: Replaced with the DTCC release of 11-Dec-2025 (S05).
A13: 9 | B13: Revenue Pools row 10 | C13: Terminal turnover of 2.5x cites SIFMA Fact Book Table 7.3. | D13: Cboe FY25 ADV of $1.1T over 251 trading days implies roughly 3.6x on the 2Q26 market cap, and about 4.0x on the FY25 average. The 2.5x terminal is not consistent with the ADV input on the Assumptions tab. Left unchanged, flagged here.
A14: 10 | B14: Revenue Pools row 18 | C14: Utilisation modelled at 15-35%. | D14: S&P Global FY25 shows average on-loan $3.25T over average lendable $46.7T, an implied utilisation of 6.96%. The modelled range is roughly 2-5x that. Left unchanged, flagged here.
A15: 11 | B15: Revenue Pools row 46 | C15: Average trade size sourced to the Cboe market share page. | D15: That page reports share by venue and does not publish trade size. Source removed; row marked FORECAST.
... A19: 15 | B19: New: Status / Src ID / Basis columns | C19: Requested. | D19: Added to Assumptions, Revenue Pools, Scenarios and Historical Analogues. VERIFIED means the figure is in the linked document. DERIVED means arithmetic on verified figures. FORECAST means judgement. UNVERIFIED means no document supports it.
